Subscripts to the `unittest.mock.call` objects now receive the same chaining mechanism as any other custom attributes, so that the following usage no longer raises a `TypeError`:

    call().foo().__getitem__('bar')

Patch by blhsing
