The :c:func:`Py_UNREACHABLE` macro now calls :c:func:`Py_FatalError`.
